<mujoco model="stretch scene">

  <include file="stretch_3.xml"/>

  <statistic center="0 0 .75" extent="1.2" meansize="0.05"/>



  <visual>

    <headlight diffuse="0.6 0.6 0.6" ambient="0.3 0.3 0.3" specular="0 0 0"/>

    <rgba haze="0.15 0.25 0.35 1"/>

    <global azimuth="-120" elevation="-20" offwidth="720" offheight="1280"/>

  </visual>



  <asset>

    <material name="mat_drawer" rgba="0.8 0.6 0.4 1" />

    <texture name="slide_metal" type="cube" height="1" width="1" file="drawer/metal1.png"/>

    <material name="slide_metal" texture="slide_metal" texrepeat="3 3" reflectance="0.7" shininess=".4" texuniform="false"/>

    <texture type="2d" name="groundplane" builtin="checker" mark="edge" rgb1="0.2 0.3 0.4" rgb2="0.1 0.2 0.3"

      markrgb="0.8 0.8 0.8" width="300" height="300"/>

    <material name="floor" texture="groundplane"/>

    <texture type="2d" name="wood" file="wood.png"/>

    <material name="wood" texture="wood"/>

    <material name="object" rgba=".2 .2 .2 1"/>

    <texture type="skybox" builtin="gradient" rgb1="0.44 0.80 1.00" rgb2="1 1 1" width="512" height="3072"/>

    <material name="shelf" rgba=".9 .9 .9 1"/>

    <material name="plastic" rgba="1 1 1 0.3" reflectance="0.4"/>

    <material name="wall" rgba=".2 .2 .2 1"/>

    

  </asset>



  <worldbody>

  <light pos="0 0 1.5" dir="0 0 -1" directional="true"/>

  <geom name="floor" size="0 0 0.05" type="plane" material="floor"/>

  <body name="render_cam" pos="-1.0 -1.0  2" quat="0.853582574770878 0.353565496535955 -0.146369166444131 -0.353366409291985">

      <camera name="render_cam" fovy="58"/>

  </body>

    <body name="Table" pos="0 0.85 0.31">
        <body name="left_leg_front" pos="-0.3 -0.15 0">
            <geom type="box" size=" 0.010  0.010  0.310" material="wall"/>
        </body>
        <body name="right_leg_front" pos="0.3 -0.15 0">
          <geom type="box" size=" 0.010  0.010  0.310" material="wall"/>
        </body>
        <body name="right_leg_back" pos="0.3 0.15 0">
          <geom type="box" size=" 0.010  0.010  0.310" material="wall"/>
        </body>
        <body name="left_leg_back" pos="-0.3 0.15 0">
          <geom type="box" size=" 0.010  0.010  0.310" material="wall"/>
        </body>
        <body name="shelf_0" pos="0 0 0.31">
          <geom type="box" size=" 0.310  0.160  0.010" material="shelf" friction="2 0.005 0.0001"/>
        </body>
    </body>

        <body name="cabinet" pos="0 0.805 0.63">
          <freejoint name="cabinet"/>
          <geom type="box" size="0.0001 0.001 0.001" mass="0.01" pos="0 0 0.12" />
          <body name="d0" pos="0 0 0.035">
              <body pos="0 0 0">
                <geom type="box" size="0.102 0.107 0.001" pos="0 0 -0.035" material="wood"/>
                <geom type="box" size="0.001 0.107 0.037" pos="-0.103 0 0.0015" material="wood"/>
                <geom type="box" size="0.001 0.107 0.037" pos="0.103 0 0.0015" material="wood"/>
                <geom type="box" size="0.102 0.107 0.001" pos="0 0 0.0385" material="wood"/>
              </body>
              <body pos="0 0 0.002">
                  <geom type="box" size="0.1 0.105 0.001" pos="0 0 -0.034" material="mat_drawer" contype="2"/>
                  <geom type="box" size="0.001 0.105 0.035" pos="-0.1 0 0" material="mat_drawer" contype="4"/>
                  <geom type="box" size="0.001 0.105 0.035" pos="0.1 0 0" material="mat_drawer" contype="4"/>
                  <geom type="box" size="0.1 0.001 0.035" pos="0 -0.105 0" material="mat_drawer" contype="8"/>
                  <body name="handle0" pos="0 -0.125 0">
                    <geom material="slide_metal" size="0.005 0.02 0.025"  type="box"/>
                  </body>
                  <joint type="slide" axis="0 -1 0" pos="0 0.105 0" range="0 0.21" damping="0.5" name="handle0"/>
              </body>
          </body>

          <body name="d1" pos="0 0 0.11">
              <body pos="0 0 0">
                <geom type="box" size="0.102 0.107 0.001" pos="0 0 -0.035" material="wood"/>
                <geom type="box" size="0.001 0.107 0.037" pos="-0.103 0 0.0015" material="wood"/>
                <geom type="box" size="0.001 0.107 0.037" pos="0.103 0 0.0015" material="wood"/>
                <geom type="box" size="0.102 0.107 0.001" pos="0 0 0.0385" material="wood"/>
              </body>
              <body pos="0 0 0.002">
                  <geom type="box" size="0.1 0.105 0.001" pos="0 0 -0.034" material="mat_drawer" contype="2"/>
                  <geom type="box" size="0.001 0.105 0.035" pos="-0.1 0 0" material="mat_drawer" contype="4"/>
                  <geom type="box" size="0.001 0.105 0.035" pos="0.1 0 0" material="mat_drawer" contype="4"/>
                  <geom type="box" size="0.1 0.001 0.035" pos="0 -0.105 0" material="mat_drawer" contype="8"/>
                  <body name="handle1" pos="0 -0.125 0">
                    <geom material="slide_metal" size="0.005 0.02 0.025"  type="box"/>
                  </body>
                  <joint type="slide" axis="0 -1 0" pos="0 0.105 0" range="0 0.21" damping="0.5" name="handle1"/>
              </body>
          </body>

          <body name="d2" pos="0 0 0.185">
              <body pos="0 0 0">
                <geom type="box" size="0.102 0.107 0.001" pos="0 0 -0.035" material="wood"/>
                <geom type="box" size="0.001 0.107 0.037" pos="-0.103 0 0.0015" material="wood"/>
                <geom type="box" size="0.001 0.107 0.037" pos="0.103 0 0.0015" material="wood"/>
                <geom type="box" size="0.102 0.107 0.001" pos="0 0 0.0385" material="wood"/>
              </body>
              <body pos="0 0 0.002">
                  <geom type="box" size="0.1 0.105 0.001" pos="0 0 -0.034" material="mat_drawer" contype="2"/>
                  <geom type="box" size="0.001 0.105 0.035" pos="-0.1 0 0" material="mat_drawer" contype="4"/>
                  <geom type="box" size="0.001 0.105 0.035" pos="0.1 0 0" material="mat_drawer" contype="4"/>
                  <geom type="box" size="0.1 0.001 0.035" pos="0 -0.105 0" material="mat_drawer" contype="8"/>
                  <body name="handle2" pos="0 -0.125 0">
                    <geom material="slide_metal" size="0.005 0.02 0.025"  type="box"/>
                  </body>
                  <joint type="slide" axis="0 -1 0" pos="0 0.105 0" range="0 0.21" damping="0.5" name="handle2"/>
              </body>
          </body>
        </body>
    </worldbody>
    </mujoco>
    